<?xml version="1.0"?>

<robot name="{{ name }}">
	<material name="black">
		<color rgba="0 0 0 0.5"/>
	</material>
	<material name="blue">
		<color rgba="0 0 1 1"/>
	</material>
	<material name="green">
		<color rgba="0 1 0 1"/>
	</material>
	<material name="red">
		<color rgba="1 0 0 1"/>
	</material>
	<material name="purple">
		<color rgba="1 0 1 1"/>
	</material>
	<material name="yellow">
		<color rgba="1 1 0 1"/>
	</material>

	{% for name, component in components %}
	<link name="{{ name }}">
		<visual>
			<geometry>
				<mesh filename="{{ component.model }}" scale="{{ scale }} {{ scale }} {{ scale }}"/>
			</geometry>
			<material name="{{ component.colour }}"/>
		</visual>
		<collision>
			<geometry>
				<mesh filename="{{ component.model }}" scale="{{ scale }} {{ scale }} {{ scale }}"/>
			</geometry>
		</collision>
		<inertial>
			<mass value="{{ component.mass }}"/>
			<inertia ixx="{{ component.ixx }}" ixy="{{ component.ixy }}" ixz="{{ component.ixz }}" iyy="{{ component.iyy }}" iyz="{{ component.iyz }}" izz="{{ component.izz }}"/>
		</inertial>
	</link>
	{% endfor %}

	{% for (parent, child, xyz, rpy, axis, servo) in joints %}
	<joint name="{{ parent }}-{{ child }}" type="revolute">
		<parent link="{{ parent }}"/>
		<child link="{{ child }}"/>
		<origin xyz="{{ xyz[0] }} {{ xyz[1] }} {{ xyz[2] }}" rpy="{{ rpy[0] }} {{ rpy[1] }} {{ rpy[2] }}"/>
		<axis xyz="{{ axis[0] }} {{ axis[1] }} {{ axis[2] }}" />
		<limit effort="{{ servo.effort }}" velocity="{{ servo.velocity }}" />
		<dynamics damping="{{ servo.damping }}" friction="{{ servo.friction }}" />
	</joint>
	{% endfor %}
</robot>

